[
    {
        "content": "<p>In Lean 3 I can do <code>try { ... } catch e =&gt; { ... }</code>. Can I do something similar in Lean 3? </p>\n<p>I'm detecting that an error is getting thrown on <a href=\"https://github.com/leanprover-community/mathlib/blob/ba2245edf0c8bb155f1569fd9b9492a9b384cde6/src/tactic/tauto.lean#L153\">this line</a>, but I don't know of a good way to examine what the error actually is.</p>",
        "id": 317084015,
        "sender_full_name": "David Renshaw",
        "timestamp": 1671598857
    },
    {
        "content": "<p>Is the code snippet in Lean 4?</p>",
        "id": 317102733,
        "sender_full_name": "Martin Dvořák",
        "timestamp": 1671610128
    },
    {
        "content": "<p>Oops, updated. Yes, the snippet is intended to be Lean 4. How do I do <code>try ... catch</code> in Lean 3?</p>",
        "id": 317145977,
        "sender_full_name": "David Renshaw",
        "timestamp": 1671625441
    },
    {
        "content": "<p>Perhaps <a href=\"https://leanprover-community.github.io/mathlib_docs/find/tactic.try_or_report_error\">docs#tactic.try_or_report_error</a></p>",
        "id": 317147866,
        "sender_full_name": "Alex J. Best",
        "timestamp": 1671626117
    },
    {
        "content": "<p>Thanks. The reported error indicated that I should do <code>set_option trace.app_builder true</code>. After doing that I no longer need to catch the error.</p>",
        "id": 317160175,
        "sender_full_name": "David Renshaw",
        "timestamp": 1671629943
    }
]