[
    {
        "content": "<p>I'm getting <a href=\"https://github.com/leanprover-community/mathlib/pull/8375/checks?check_run_id=3114964848\">the following CI failure</a> that I don't understand:</p>\n<div class=\"codehilite\" data-code-language=\"Text only\"><pre><span></span><code>Setting up auth\n  /usr/bin/git config --local --name-only --get-regexp core\\.sshCommand\n  /usr/bin/git submodule foreach --recursive git config --local --name-only --get-regexp 'core\\.sshCommand' &amp;&amp; git config --local --unset-all 'core.sshCommand' || :\n  Error: fatal: No url found for submodule path 'class-number' in .gitmodules\n  Error: The process '/usr/bin/git' failed with exit code 128\n</code></pre></div>\n<p>The only relation I can think of is that the Lean Forward organisation has a separate <code>class-number</code> repository that has mathlib as a dependency, but this commit was made on a clean copy of mathlib master. And neither repository has a <code>.gitmodules</code> file AFAICT</p>",
        "id": 246596607,
        "sender_full_name": "Anne Baanen",
        "timestamp": 1626791708
    },
    {
        "content": "<p>Other CI jobs with the same \"Setting up auth\" rule pass, but restarting the build doesn't seem to help.</p>",
        "id": 246597416,
        "sender_full_name": "Anne Baanen",
        "timestamp": 1626791863
    },
    {
        "content": "<p>Likewise I've suddenly started hitting this and I'm very confused. It is surely a coincidence but I've been tidying up <a href=\"https://github.com/leanprover-community/mathlib/tree/p-adic\">branch#p-adic</a> and just removed an empty folder (in that branch) called <code>class-number</code>!</p>",
        "id": 246598612,
        "sender_full_name": "Oliver Nash",
        "timestamp": 1626792125
    },
    {
        "content": "<p><a href=\"https://github.com/leanprover-community/mathlib/runs/3115085697#step:2:149\">https://github.com/leanprover-community/mathlib/runs/3115085697#step:2:149</a> is the same</p>",
        "id": 246598870,
        "sender_full_name": "Eric Wieser",
        "timestamp": 1626792164
    },
    {
        "content": "<p>Is there any reason why <code>class-number</code> could have ended up on the CI runners?<br>\nAnd is there a chance that CI runs aren't cleaning up after themselves well enough?</p>",
        "id": 246599159,
        "sender_full_name": "Johan Commelin",
        "timestamp": 1626792219
    },
    {
        "content": "<p>I haven't touched the <code>class-number</code> repo in a couple of weeks, it's in a different organisation and I don't think it involves any submodules. So I don't think that's the cause.</p>",
        "id": 246599896,
        "sender_full_name": "Anne Baanen",
        "timestamp": 1626792348
    },
    {
        "content": "<p>CI runners keeping around a bit too much state sounds possible.</p>",
        "id": 246599959,
        "sender_full_name": "Anne Baanen",
        "timestamp": 1626792363
    },
    {
        "content": "<p>Git doesn't track directories, so removing an empty directory from the repository sounds a bit suspicious...</p>",
        "id": 246600369,
        "sender_full_name": "Anne Baanen",
        "timestamp": 1626792449
    },
    {
        "content": "<p>Here's the commit where I remove an empty folder called <code>class-number</code>: <a href=\"https://github.com/leanprover-community/mathlib/commit/de03792d96f51fccc2813f98c156dca62b803173\">https://github.com/leanprover-community/mathlib/commit/de03792d96f51fccc2813f98c156dca62b803173</a> but I _now_ note that earlier commits on that branch also hit the same error.</p>",
        "id": 246600559,
        "sender_full_name": "Oliver Nash",
        "timestamp": 1626792511
    },
    {
        "content": "<p>Yeah, looking at the diff saying \"Submodule class-number deleted from 6330d4\" this seems to be almost directly connected.</p>",
        "id": 246601168,
        "sender_full_name": "Anne Baanen",
        "timestamp": 1626792618
    },
    {
        "content": "<p><a href=\"https://github.com/actions/checkout/issues/354\">https://github.com/actions/checkout/issues/354</a></p>",
        "id": 246601845,
        "sender_full_name": "Eric Wieser",
        "timestamp": 1626792903
    },
    {
        "content": "<p>And also <a href=\"https://github.com/actions/checkout/issues/385\">https://github.com/actions/checkout/issues/385</a></p>",
        "id": 246601923,
        "sender_full_name": "Eric Wieser",
        "timestamp": 1626792945
    },
    {
        "content": "<p>Which is specific to self-hoster runners</p>",
        "id": 246601932,
        "sender_full_name": "Eric Wieser",
        "timestamp": 1626792951
    },
    {
        "content": "<p>Good find! That sounds very related to the problems we are seeing!</p>",
        "id": 246602259,
        "sender_full_name": "Johan Commelin",
        "timestamp": 1626793083
    },
    {
        "content": "<p>So for now we can just clean up the worker and hope no one ever makes a submodule again</p>",
        "id": 246602335,
        "sender_full_name": "Eric Wieser",
        "timestamp": 1626793116
    },
    {
        "content": "<p>Issue 385 seems to be exactly what is going on here. Would a CI step that removes <code>.gitmodules</code> before checkout fix this?</p>",
        "id": 246602346,
        "sender_full_name": "Anne Baanen",
        "timestamp": 1626793120
    },
    {
        "content": "<p>Seems worth trying!</p>",
        "id": 246604251,
        "sender_full_name": "Bryan Gin-ge Chen",
        "timestamp": 1626793770
    },
    {
        "content": "<p>(I should add that I can't work on this until tonight, so if someone wants to take a shot at it, please do!)</p>",
        "id": 246606634,
        "sender_full_name": "Bryan Gin-ge Chen",
        "timestamp": 1626794798
    }
]